Workbook

Sheet Categorias
B2: CATEGORIAS
B4: Establece nombres de categorías y subcategorías para tus ingresos y gastos. Elimina las que no necesitas, cambia, o añade nuevas. Los cambios que realices aquí, se cambian automaticamente en todos los meses.
B7: Lista de categorías
B9: Ingresos
B11: INGRESOS TOTALES
B12: Nomina
B13: Aguinaldo
B14: Fondo de ahorro
B15: Vales despensa
B16: Vales comedor
B17: -
B18: -
... B164: -

Sheet TODO EL AÑO
B2: Presupuesto | C2: AÑO 2026
C4: En este lugar no llenas nada. Es una vista del presupuesto de todo el año y todo se hará automicamente después de llenar los datos en los meses, de Enero hasta Diciembre - Todos los otros datos se convertirán automáticamente
C5: Fuente: | D5: =HYPERLINK("http://www.aprendizfinanciero.com/","http://www.aprendizfinanciero.com") -> http://www.aprendizfinanciero.com
B6: Ingresos
B8: Categoría | C8: Ingresos previstos | D8: Ingresos reales | E8: Diferencia | F8: Notas
B9: SUMA | C9: =C11 -> 467281.6 | D9: =D11 -> 324561.2 | E9: =E11 -> -142720.4
B11: =Categorias!B11 -> INGRESOS TOTALES | C11: =SUM(C12:C20) -> 467281.6 | D11: =SUM(D12:D20) -> 324561.2 | E11: =SUM(E12:E20) -> -142720.4
B12: =Categorias!B12 -> Nomina | C12: =Enero!C12+Febrero!C12+Marzo!C12+Abril!C12+Mayo!C12+Junio!C12+Julio!C12+Agosto!C12+Septiembre!C12+Octubre!C12+Noviembre!C12+Diciembre!C12 -> 442881.6 | D12: =Enero!D12+Febrero!D12+Marzo!D12+Abril!D12+Mayo!D12+Junio!D12+Julio!D12+Agosto!D12+Septiembre!D12+Octubre!D12+Noviembre!D12+Diciembre!D12 -> 308161.2 | E12: =D12-C12 -> -134720.4
B13: =Categorias!B13 -> Aguinaldo | C13: =Enero!C13+Febrero!C13+Marzo!C13+Abril!C13+Mayo!C13+Junio!C13+Julio!C13+Agosto!C13+Septiembre!C13+Octubre!C13+Noviembre!C13+Diciembre!C13 -> 15000 | D13: =Enero!D13+Febrero!D13+Marzo!D13+Abril!D13+Mayo!D13+Junio!D13+Julio!D13+Agosto!D13+Septiembre!D13+Octubre!D13+Noviembre!D13+Diciembre!D13 -> 10000 | E13: =D13-C13 -> -5000
B14: =Categorias!B14 -> Fondo de ahorro | C14: =Enero!C14+Febrero!C14+Marzo!C14+Abril!C14+Mayo!C14+Junio!C14+Julio!C14+Agosto!C14+Septiembre!C14+Octubre!C14+Noviembre!C14+Diciembre!C14 -> 0 | D14: =Enero!D14+Febrero!D14+Marzo!D14+Abril!D14+Mayo!D14+Junio!D14+Julio!D14+Agosto!D14+Septiembre!D14+Octubre!D14+Noviembre!D14+Diciembre!D14 -> 0 | E14: =D14-C14 -> 0
B15: =Categorias!B15 -> Vales despensa | C15: =Enero!C15+Febrero!C15+Marzo!C15+Abril!C15+Mayo!C15+Junio!C15+Julio!C15+Agosto!C15+Septiembre!C15+Octubre!C15+Noviembre!C15+Diciembre!C15 -> 9400 | D15: =Enero!D15+Febrero!D15+Marzo!D15+Abril!D15+Mayo!D15+Junio!D15+Julio!D15+Agosto!D15+Septiembre!D15+Octubre!D15+Noviembre!D15+Diciembre!D15 -> 6400 | E15: =D15-C15 -> -3000
B16: =Categorias!B16 -> Vales comedor | C16: =Enero!C16+Febrero!C16+Marzo!C16+Abril!C16+Mayo!C16+Junio!C16+Julio!C16+Agosto!C16+Septiembre!C16+Octubre!C16+Noviembre!C16+Diciembre!C16 -> 0 | D16: =Enero!D16+Febrero!D16+Marzo!D16+Abril!D16+Mayo!D16+Junio!D16+Julio!D16+Agosto!D16+Septiembre!D16+Octubre!D16+Noviembre!D16+Diciembre!D16 -> 0 | E16: =D16-C16 -> 0
B17: =Categorias!B17 -> - | C17: =Enero!C17+Febrero!C17+Marzo!C17+Abril!C17+Mayo!C17+Junio!C17+Julio!C17+Agosto!C17+Septiembre!C17+Octubre!C17+Noviembre!C17+Diciembre!C17 -> 0 | D17: =Enero!D17+Febrero!D17+Marzo!D17+Abril!D17+Mayo!D17+Junio!D17+Julio!D17+Agosto!D17+Septiembre!D17+Octubre!D17+Noviembre!D17+Diciembre!D17 -> 0 | E17: =D17-C17 -> 0
B18: =Categorias!B18 -> - | C18: =Enero!C18+Febrero!C18+Marzo!C18+Abril!C18+Mayo!C18+Junio!C18+Julio!C18+Agosto!C18+Septiembre!C18+Octubre!C18+Noviembre!C18+Diciembre!C18 -> 0 | D18: =Enero!D18+Febrero!D18+Marzo!D18+Abril!D18+Mayo!D18+Junio!D18+Julio!D18+Agosto!D18+Septiembre!D18+Octubre!D18+Noviembre!D18+Diciembre!D18 -> 0 | E18: =D18-C18 -> 0
B19: =Categorias!B19 -> - | C19: =Enero!C19+Febrero!C19+Marzo!C19+Abril!C19+Mayo!C19+Junio!C19+Julio!C19+Agosto!C19+Septiembre!C19+Octubre!C19+Noviembre!C19+Diciembre!C19 -> 0 | D19: =Enero!D19+Febrero!D19+Marzo!D19+Abril!D19+Mayo!D19+Junio!D19+Julio!D19+Agosto!D19+Septiembre!D19+Octubre!D19+Noviembre!D19+Diciembre!D19 -> 0 | E19: =D19-C19 -> 0
B20: =Categorias!B20 -> - | C20: =Enero!C20+Febrero!C20+Marzo!C20+Abril!C20+Mayo!C20+Junio!C20+Julio!C20+Agosto!C20+Septiembre!C20+Octubre!C20+Noviembre!C20+Diciembre!C20 -> 0 | D20: =Enero!D20+Febrero!D20+Marzo!D20+Abril!D20+Mayo!D20+Junio!D20+Julio!D20+Agosto!D20+Septiembre!D20+Octubre!D20+Noviembre!D20+Diciembre!D20 -> 0 | E20: =D20-C20 -> 0
B23: Gastos
B25: Categoría | C25: Gastos previstos | D25: Gastos reales | E25: Diferencia | F25: Notas
B26: SUMA | C26: =C28+C37+C45+C58+C68+C77+C88+C97+C107+C115+C126+C136+C146+C158 -> 322192.45 | D26: =D28+D37+D45+D58+D68+D77+D88+D97+D107+D115+D126+D136+D146+D158 -> 304907.15 | E26: =E28+E37+E45+E58+E68+E77+E88+E97+E107+E115+E126+E136+E146+E158 -> 17285.3
B28: =Categorias!B24 -> ALIMENTOS Y BEBIDAS | C28: =SUM(C29:C35) -> 29000 | D28: =SUM(D29:D35) -> 44168.02 | E28: =SUM(E29:E35) -> -15168.02
B29: =Categorias!B25 -> Restaurantes | C29: =Enero!C29+Febrero!C29+Marzo!C29+Abril!C29+Mayo!C29+Junio!C29+Julio!C29+Agosto!C29+Septiembre!C29+Octubre!C29+Noviembre!C29+Diciembre!C29 -> 20500 | D29: =Enero!D29+Febrero!D29+Marzo!D29+Abril!D29+Mayo!D29+Junio!D29+Julio!D29+Agosto!D29+Septiembre!D29+Octubre!D29+Noviembre!D29+Diciembre!D29 -> 34421.82 | E29: =C29-D29 -> -13921.82
B30: =Categorias!B26 -> Comida Carlos | C30: =Enero!C30+Febrero!C30+Marzo!C30+Abril!C30+Mayo!C30+Junio!C30+Julio!C30+Agosto!C30+Septiembre!C30+Octubre!C30+Noviembre!C30+Diciembre!C30 -> 6500 | D30: =Enero!D30+Febrero!D30+Marzo!D30+Abril!D30+Mayo!D30+Junio!D30+Julio!D30+Agosto!D30+Septiembre!D30+Octubre!D30+Noviembre!D30+Diciembre!D30 -> 6362.6 | E30: =C30-D30 -> 137.4
B31: =Categorias!B27 -> - | C31: =Enero!C31+Febrero!C31+Marzo!C31+Abril!C31+Mayo!C31+Junio!C31+Julio!C31+Agosto!C31+Septiembre!C31+Octubre!C31+Noviembre!C31+Diciembre!C31 -> 1000 | D31: =Enero!D31+Febrero!D31+Marzo!D31+Abril!D31+Mayo!D31+Junio!D31+Julio!D31+Agosto!D31+Septiembre!D31+Octubre!D31+Noviembre!D31+Diciembre!D31 -> 505.6 | E31: =C31-D31 -> 494.4
B32: =Categorias!B28 -> - | C32: =Enero!C32+Febrero!C32+Marzo!C32+Abril!C32+Mayo!C32+Junio!C32+Julio!C32+Agosto!C32+Septiembre!C32+Octubre!C32+Noviembre!C32+Diciembre!C32 -> 1000 | D32: =Enero!D32+Febrero!D32+Marzo!D32+Abril!D32+Mayo!D32+Junio!D32+Julio!D32+Agosto!D32+Septiembre!D32+Octubre!D32+Noviembre!D32+Diciembre!D32 -> 1941 | E32: =C32-D32 -> -941
B33: =Categorias!B29 -> - | C33: =Enero!C33+Febrero!C33+Marzo!C33+Abril!C33+Mayo!C33+Junio!C33+Julio!C33+Agosto!C33+Septiembre!C33+Octubre!C33+Noviembre!C33+Diciembre!C33 -> 0 | D33: =Enero!D33+Febrero!D33+Marzo!D33+Abril!D33+Mayo!D33+Junio!D33+Julio!D33+Agosto!D33+Septiembre!D33+Octubre!D33+Noviembre!D33+Diciembre!D33 -> 657 | E33: =C33-D33 -> -657
B34: =Categorias!B30 -> - | C34: =Enero!C34+Febrero!C34+Marzo!C34+Abril!C34+Mayo!C34+Junio!C34+Julio!C34+Agosto!C34+Septiembre!C34+Octubre!C34+Noviembre!C34+Diciembre!C34 -> 0 | D34: =Enero!D34+Febrero!D34+Marzo!D34+Abril!D34+Mayo!D34+Junio!D34+Julio!D34+Agosto!D34+Septiembre!D34+Octubre!D34+Noviembre!D34+Diciembre!D34 -> 280 | E34: =C34-D34 -> -280
B35: =Categorias!B31 -> - | C35: =Enero!C35+Febrero!C35+Marzo!C35+Abril!C35+Mayo!C35+Junio!C35+Julio!C35+Agosto!C35+Septiembre!C35+Octubre!C35+Noviembre!C35+Diciembre!C35 -> 0 | D35: =Enero!D35+Febrero!D35+Marzo!D35+Abril!D35+Mayo!D35+Junio!D35+Julio!D35+Agosto!D35+Septiembre!D35+Octubre!D35+Noviembre!D35+Diciembre!D35 -> 0 | E35: =C35-D35 -> 0
B37: =Categorias!B33 -> SALUD | C37: =Enero!C37+Febrero!C37+Marzo!C37+Abril!C37+Mayo!C37+Junio!C37+Julio!C37+Agosto!C37+Septiembre!C37+Octubre!C37+Noviembre!C37+Diciembre!C37 -> 13500 | D37: =Enero!D37+Febrero!D37+Marzo!D37+Abril!D37+Mayo!D37+Junio!D37+Julio!D37+Agosto!D37+Septiembre!D37+Octubre!D37+Noviembre!D37+Diciembre!D37 -> 15428.4 | E37: =SUM(E38:E43) -> -1928.4
B38: =Categorias!B34 -> Gastos en médicos | C38: =Enero!C38+Febrero!C38+Marzo!C38+Abril!C38+Mayo!C38+Junio!C38+Julio!C38+Agosto!C38+Septiembre!C38+Octubre!C38+Noviembre!C38+Diciembre!C38 -> 5000 | D38: =Enero!D38+Febrero!D38+Marzo!D38+Abril!D38+Mayo!D38+Junio!D38+Julio!D38+Agosto!D38+Septiembre!D38+Octubre!D38+Noviembre!D38+Diciembre!D38 -> 3080 | E38: =C38-D38 -> 1920
B39: =Categorias!B35 -> Medicamentos | C39: =Enero!C39+Febrero!C39+Marzo!C39+Abril!C39+Mayo!C39+Junio!C39+Julio!C39+Agosto!C39+Septiembre!C39+Octubre!C39+Noviembre!C39+Diciembre!C39 -> 2000 | D39: =Enero!D39+Febrero!D39+Marzo!D39+Abril!D39+Mayo!D39+Junio!D39+Julio!D39+Agosto!D39+Septiembre!D39+Octubre!D39+Noviembre!D39+Diciembre!D39 -> 11848.4 | E39: =C39-D39 -> -9848.4
B40: =Categorias!B36 -> Dentista Kary | C40: =Enero!C40+Febrero!C40+Marzo!C40+Abril!C40+Mayo!C40+Junio!C40+Julio!C40+Agosto!C40+Septiembre!C40+Octubre!C40+Noviembre!C40+Diciembre!C40 -> 4100 | D40: =Enero!D40+Febrero!D40+Marzo!D40+Abril!D40+Mayo!D40+Junio!D40+Julio!D40+Agosto!D40+Septiembre!D40+Octubre!D40+Noviembre!D40+Diciembre!D40 -> 500 | E40: =C40-D40 -> 3600
B41: =Categorias!B37 -> Dentista Thiago | C41: =Enero!C41+Febrero!C41+Marzo!C41+Abril!C41+Mayo!C41+Junio!C41+Julio!C41+Agosto!C41+Septiembre!C41+Octubre!C41+Noviembre!C41+Diciembre!C41 -> 2400 | D41: =Enero!D41+Febrero!D41+Marzo!D41+Abril!D41+Mayo!D41+Junio!D41+Julio!D41+Agosto!D41+Septiembre!D41+Octubre!D41+Noviembre!D41+Diciembre!D41 -> 0 | E41: =C41-D41 -> 2400
B42: =Categorias!B38 -> - | C42: =Enero!C42+Febrero!C42+Marzo!C42+Abril!C42+Mayo!C42+Junio!C42+Julio!C42+Agosto!C42+Septiembre!C42+Octubre!C42+Noviembre!C42+Diciembre!C42 -> 0 | D42: =Enero!D42+Febrero!D42+Marzo!D42+Abril!D42+Mayo!D42+Junio!D42+Julio!D42+Agosto!D42+Septiembre!D42+Octubre!D42+Noviembre!D42+Diciembre!D42 -> 0 | E42: =C42-D42 -> 0
B43: =Categorias!B39 -> - | C43: =Enero!C43+Febrero!C43+Marzo!C43+Abril!C43+Mayo!C43+Junio!C43+Julio!C43+Agosto!C43+Septiembre!C43+Octubre!C43+Noviembre!C43+Diciembre!C43 -> 0 | D43: =Enero!D43+Febrero!D43+Marzo!D43+Abril!D43+Mayo!D43+Junio!D43+Julio!D43+Agosto!D43+Septiembre!D43+Octubre!D43+Noviembre!D43+Diciembre!D43 -> 0 | E43: =C43-D43 -> 0
B45: =Categorias!B41 -> CASA | C45: =Enero!C45+Febrero!C45+Marzo!C45+Abril!C45+Mayo!C45+Junio!C45+Julio!C45+Agosto!C45+Septiembre!C45+Octubre!C45+Noviembre!C45+Diciembre!C45 -> 108340 | D45: =Enero!D45+Febrero!D45+Marzo!D45+Abril!D45+Mayo!D45+Junio!D45+Julio!D45+Agosto!D45+Septiembre!D45+Octubre!D45+Noviembre!D45+Diciembre!D45 -> 106460 | E45: =SUM(E46:E56) -> 1880
B46: =Categorias!B42 -> Reparación | C46: =Enero!C46+Febrero!C46+Marzo!C46+Abril!C46+Mayo!C46+Junio!C46+Julio!C46+Agosto!C46+Septiembre!C46+Octubre!C46+Noviembre!C46+Diciembre!C46 -> 500 | D46: =Enero!D46+Febrero!D46+Marzo!D46+Abril!D46+Mayo!D46+Junio!D46+Julio!D46+Agosto!D46+Septiembre!D46+Octubre!D46+Noviembre!D46+Diciembre!D46 -> 24002 | E46: =C46-D46 -> -23502
B47: =Categorias!B43 -> Electricidad | C47: =Enero!C47+Febrero!C47+Marzo!C47+Abril!C47+Mayo!C47+Junio!C47+Julio!C47+Agosto!C47+Septiembre!C47+Octubre!C47+Noviembre!C47+Diciembre!C47 -> 6700 | D47: =Enero!D47+Febrero!D47+Marzo!D47+Abril!D47+Mayo!D47+Junio!D47+Julio!D47+Agosto!D47+Septiembre!D47+Octubre!D47+Noviembre!D47+Diciembre!D47 -> 3553 | E47: =C47-D47 -> 3147
B48: =Categorias!B44 -> Gas | C48: =Enero!C48+Febrero!C48+Marzo!C48+Abril!C48+Mayo!C48+Junio!C48+Julio!C48+Agosto!C48+Septiembre!C48+Octubre!C48+Noviembre!C48+Diciembre!C48 -> 2640 | D48: =Enero!D48+Febrero!D48+Marzo!D48+Abril!D48+Mayo!D48+Junio!D48+Julio!D48+Agosto!D48+Septiembre!D48+Octubre!D48+Noviembre!D48+Diciembre!D48 -> 850 | E48: =C48-D48 -> 1790
B49: =Categorias!B45 -> Casa Claudia | C49: =Enero!C49+Febrero!C49+Marzo!C49+Abril!C49+Mayo!C49+Junio!C49+Julio!C49+Agosto!C49+Septiembre!C49+Octubre!C49+Noviembre!C49+Diciembre!C49 -> 12500 | D49: =Enero!D49+Febrero!D49+Marzo!D49+Abril!D49+Mayo!D49+Junio!D49+Julio!D49+Agosto!D49+Septiembre!D49+Octubre!D49+Noviembre!D49+Diciembre!D49 -> 8063 | E49: =C49-D49 -> 4437
B50: =Categorias!B46 -> Muebles/electrodomésticos | C50: =Enero!C50+Febrero!C50+Marzo!C50+Abril!C50+Mayo!C50+Junio!C50+Julio!C50+Agosto!C50+Septiembre!C50+Octubre!C50+Noviembre!C50+Diciembre!C50 -> 0 | D50: =Enero!D50+Febrero!D50+Marzo!D50+Abril!D50+Mayo!D50+Junio!D50+Julio!D50+Agosto!D50+Septiembre!D50+Octubre!D50+Noviembre!D50+Diciembre!D50 -> 6642 | E50: =C50-D50 -> -6642
...

Sheet Enero
B2: Presupuesto | C2: 45292
C4: Para crear un presupuesto: - A principios de este mes, rellene los campos en amarillo, despues de forma regular registre los gastos de cada dia en la tabla a la derecha - Todos los otros datos se convertirá automáticamente
C5: Fuente: | D5: =HYPERLINK("http://www.aprendizfinanciero.com/","http://www.aprendizfinanciero.com") -> http://www.aprendizfinanciero.com
B6: Ingresos
B8: Categoría | C8: Ingresos previstos | D8: Ingresos reales | E8: Diferencia | F8: Notas
B9: SUMA | C9: =C11 -> 53400 | D9: =D11 -> 26400 | E9: =E11 -> -27000
B11: =Categorias!B11 -> INGRESOS TOTALES | C11: =SUM(C12:C20) -> 53400 | D11: =SUM(D12:D20) -> 26400 | E11: =SUM(E12:E20) -> -27000 | H11: 1 | I11: 2 | J11: 3 | K11: 4 | L11: 5 | M11: 6 | N11: 7 | O11: 8 | P11: 9 | Q11: 10 | R11: 11 | S11: 12 | T11: 13 | U11: 14 | V11: 15 | W11: 16 | X11: 17 | Y11: 18 | Z11: 19 | AA11: 20 | AB11: 21 | AC11: 22 | AD11: 23 | AE11: 24 | AF11: 25 | AG11: 26 | AH11: 27 | AI11: 28 | AJ11: 29 | AK11: 30 | AL11: 31
B12: =Categorias!B12 -> Nomina | C12: 50000 | D12: =SUM(Enero!$H12:$AL12) -> 23000 | E12: =D12-C12 -> -27000 | H12: 23000
B13: =Categorias!B13 -> Aguinaldo | C13: 0 | D13: =SUM(Enero!$H13:$AL13) -> 0 | E13: =D13-C13 -> 0
B14: =Categorias!B14 -> Fondo de ahorro | C14: 0 | D14: =SUM(Enero!$H14:$AL14) -> 0 | E14: =D14-C14 -> 0
B15: =Categorias!B15 -> Vales despensa | C15: 3400 | D15: =SUM(Enero!$H15:$AL15) -> 3400 | E15: =D15-C15 -> 0 | H15: 3400
B16: =Categorias!B16 -> Vales comedor | C16: 0 | D16: =SUM(Enero!$H16:$AL16) -> 0 | E16: =D16-C16 -> 0
B17: =Categorias!B17 -> - | C17: 0 | D17: =SUM(Enero!$H17:$AL17) -> 0 | E17: =D17-C17 -> 0
B18: =Categorias!B18 -> - | C18: 0 | D18: =SUM(Enero!$H18:$AL18) -> 0 | E18: =D18-C18 -> 0
B19: =Categorias!B19 -> - | C19: 0 | D19: =SUM(Enero!$H19:$AL19) -> 0 | E19: =D19-C19 -> 0
B20: =Categorias!B20 -> - | C20: 0 | D20: =SUM(Enero!$H20:$AL20) -> 0 | E20: =D20-C20 -> 0
B23: Gastos | H23: Registro de gastos diarios
B25: Categoría | C25: Gastos previstos | D25: Gastos reales | E25: Diferencia | F25: Notas | H25: Los campos siguientes son para un registro diario de gastos en cada categoría.
B26: SUMA | C26: =C28+C37+C45+C58+C68+C77+C88+C97+C107+C115+C126+C136+C146+C158 -> 59100 | D26: =D28+D37+D45+D58+D68+D77+D88+D97+D107+D115+D126+D136+D146+D158 -> 48977.83 | E26: =E28+E37+E45+E58+E68+E77+E88+E97+E107+E115+E126+E136+E146+E158 -> 10122.17 | H26: Si quieres incluir mas gastos en una celda, por el mismo dia, ingresa "=" y sigue la ecuación, por ejemplo:. = 25 + 20.5
B28: =Categorias!B24 -> ALIMENTOS Y BEBIDAS | C28: =SUM(C29:C35) -> 5000 | D28: =SUM(D29:D35) -> 9325 | E28: =SUM(E29:E35) -> -4325 | H28: 1 | I28: 2 | J28: 3 | K28: 4 | L28: 5 | M28: 6 | N28: 7 | O28: 8 | P28: 9 | Q28: 10 | R28: 11 | S28: 12 | T28: 13 | U28: 14 | V28: 15 | W28: 16 | X28: 17 | Y28: 18 | Z28: 19 | AA28: 20 | AB28: 21 | AC28: 22 | AD28: 23 | AE28: 24 | AF28: 25 | AG28: 26 | AH28: 27 | AI28: 28 | AJ28: 29 | AK28: 30 | AL28: 31
B29: =Categorias!B25 -> Restaurantes | C29: 0 | D29: =SUM(Enero!$H29:$AL29) -> 7710 | E29: =C29-D29 -> -7710 | J29: 460 | L29: 980 | M29: 430 | O29: 70 | P29: 750 | Q29: 1300 | R29: 320 | U29: 423 | V29: 180 | W29: 370 | X29: 235 | Y29: 176 | Z29: 882 | AA29: 136 | AB29: 219 | AC29: 505 | AD29: 204 | AE29: 70
B30: =Categorias!B26 -> Comida Carlos | C30: 5000 | D30: =SUM(Enero!$H30:$AL30) -> 1615 | E30: =C30-D30 -> 3385 | W30: 432 | X30: 297 | Y30: 164 | AA30: 90 | AB30: 80 | AE30: 552
B31: =Categorias!B27 -> - | C31: 0 | D31: =SUM(Enero!$H31:$AL31) -> 0 | E31: =C31-D31 -> 0
B32: =Categorias!B28 -> - | C32: 0 | D32: =SUM(Enero!$H32:$AL32) -> 0 | E32: =C32-D32 -> 0
B33: =Categorias!B29 -> - | C33: 0 | D33: =SUM(Enero!$H33:$AL33) -> 0 | E33: =C33-D33 -> 0
B34: =Categorias!B30 -> - | C34: 0 | D34: =SUM(Enero!$H34:$AL34) -> 0 | E34: =C34-D34 -> 0
B35: =Categorias!B31 -> - | C35: 0 | D35: =SUM(Enero!$H35:$AL35) -> 0 | E35: =C35-D35 -> 0
B37: =Categorias!B33 -> SALUD | C37: =SUM(C38:C43) -> 1000 | D37: =SUM(D38:D43) -> 1229 | E37: =SUM(E38:E43) -> -229 | H37: 1 | I37: 2 | J37: 3 | K37: 4 | L37: 5 | M37: 6 | N37: 7 | O37: 8 | P37: 9 | Q37: 10 | R37: 11 | S37: 12 | T37: 13 | U37: 14 | V37: 15 | W37: 16 | X37: 17 | Y37: 18 | Z37: 19 | AA37: 20 | AB37: 21 | AC37: 22 | AD37: 23 | AE37: 24 | AF37: 25 | AG37: 26 | AH37: 27 | AI37: 28 | AJ37: 29 | AK37: 30 | AL37: 31
B38: =Categorias!B34 -> Gastos en médicos | C38: 0 | D38: =SUM(Enero!$H38:$AL38) -> 0 | E38: =C38-D38 -> 0
B39: =Categorias!B35 -> Medicamentos | C39: 1000 | D39: =SUM(Enero!$H39:$AL39) -> 1229 | E39: =C39-D39 -> -229 | J39: 300 | AA39: 929
B40: =Categorias!B36 -> Dentista Kary | C40: 0 | D40: =SUM(Enero!$H40:$AL40) -> 0 | E40: =C40-D40 -> 0
B41: =Categorias!B37 -> Dentista Thiago | C41: 0 | D41: =SUM(Enero!$H41:$AL41) -> 0 | E41: =C41-D41 -> 0
B42: =Categorias!B38 -> - | C42: 0 | D42: =SUM(Enero!$H42:$AL42) -> 0 | E42: =C42-D42 -> 0
B43: =Categorias!B39 -> - | C43: 0 | D43: =SUM(Enero!$H43:$AL43) -> 0 | E43: =C43-D43 -> 0
B45: =Categorias!B41 -> CASA | C45: =SUM(C46:C56) -> 29700 | D45: =SUM(D46:D56) -> 23585 | E45: =SUM(E46:E56) -> 6115 | H45: 1 | I45: 2 | J45: 3 | K45: 4 | L45: 5 | M45: 6 | N45: 7 | O45: 8 | P45: 9 | Q45: 10 | R45: 11 | S45: 12 | T45: 13 | U45: 14 | V45: 15 | W45: 16 | X45: 17 | Y45: 18 | Z45: 19 | AA45: 20 | AB45: 21 | AC45: 22 | AD45: 23 | AE45: 24 | AF45: 25 | AG45: 26 | AH45: 27 | AI45: 28 | AJ45: 29 | AK45: 30 | AL45: 31
B46: =Categorias!B42 -> Reparación | C46: 0 | D46: =SUM(Enero!$H46:$AL46) -> 345 | E46: =C46-D46 -> -345 | O46: 345
B47: =Categorias!B43 -> Electricidad | C47: 2500 | D47: =SUM(Enero!$H47:$AL47) -> 0 | E47: =C47-D47 -> 2500
B48: =Categorias!B44 -> Gas | C48: 200 | D48: =SUM(Enero!$H48:$AL48) -> 0 | E48: =C48-D48 -> 200
B49: =Categorias!B45 -> Casa Claudia | C49: 12400 | D49: =SUM(Enero!$H49:$AL49) -> 7900 | E49: =C49-D49 -> 4500 | H49: 4500 | I49: 3400
B50: =Categorias!B46 -> Muebles/electrodomésticos | C50: 0 | D50: =SUM(Enero!$H50:$AL50) -> 1340 | E50: =C50-D50 -> -1340 | L50: 350 | X50: 370 | AA50: 300 | AD50: 320
...

Sheet Febrero
B2: Presupuesto | C2: 44958
C4: Para crear un presupuesto: - A principios de este mes, rellene los campos en amarillo, despues de forma regular registre los gastos de cada dia en la tabla a la derecha - Todos los otros datos se convertirá automáticamente
C5: Fuente: | D5: =HYPERLINK("http://www.aprendizfinanciero.com/","http://www.aprendizfinanciero.com") -> http://www.aprendizfinanciero.com
B6: Ingresos
B8: Categoría | C8: Ingresos previstos | D8: Ingresos reales | E8: Diferencia | F8: Notas
B9: SUMA | C9: =C11 -> 44000 | D9: =D11 -> 0 | E9: =E11 -> -44000
B11: =Categorias!B11 -> INGRESOS TOTALES | C11: =SUM(C12:C20) -> 44000 | D11: =SUM(D12:D20) -> 0 | E11: =SUM(E12:E20) -> -44000 | H11: 1 | I11: 2 | J11: 3 | K11: 4 | L11: 5 | M11: 6 | N11: 7 | O11: 8 | P11: 9 | Q11: 10 | R11: 11 | S11: 12 | T11: 13 | U11: 14 | V11: 15 | W11: 16 | X11: 17 | Y11: 18 | Z11: 19 | AA11: 20 | AB11: 21 | AC11: 22 | AD11: 23 | AE11: 24 | AF11: 25 | AG11: 26 | AH11: 27 | AI11: 28 | AJ11: 29 | AK11: 30 | AL11: 31
B12: =Categorias!B12 -> Nomina | C12: 44000 | D12: =SUM(Febrero!$H12:$AL12) -> 0 | E12: =D12-C12 -> -44000
B13: =Categorias!B13 -> Aguinaldo | C13: 0 | D13: =SUM(Febrero!$H13:$AL13) -> 0 | E13: =D13-C13 -> 0
B14: =Categorias!B14 -> Fondo de ahorro | C14: 0 | D14: =SUM(Febrero!$H14:$AL14) -> 0 | E14: =D14-C14 -> 0
B15: =Categorias!B15 -> Vales despensa | C15: 0 | D15: =SUM(Febrero!$H15:$AL15) -> 0 | E15: =D15-C15 -> 0
B16: =Categorias!B16 -> Vales comedor | C16: 0 | D16: =SUM(Febrero!$H16:$AL16) -> 0 | E16: =D16-C16 -> 0
B17: =Categorias!B17 -> - | C17: 0 | D17: =SUM(Febrero!$H17:$AL17) -> 0 | E17: =D17-C17 -> 0
B18: =Categorias!B18 -> - | C18: 0 | D18: =SUM(Febrero!$H18:$AL18) -> 0 | E18: =D18-C18 -> 0
B19: =Categorias!B19 -> - | C19: 0 | D19: =SUM(Febrero!$H19:$AL19) -> 0 | E19: =D19-C19 -> 0
B20: =Categorias!B20 -> - | C20: 0 | D20: =SUM(Febrero!$H20:$AL20) -> 0 | E20: =D20-C20 -> 0
B23: Gastos | H23: Registre de gastos diarios
B25: Categoría | C25: Gastos previstos | D25: Gastos reales | E25: Diferencia | F25: Notas | H25: Los campos siguientes son para un registro diario de gastos en cada categoría.
B26: SUMA | C26: =C28+C37+C45+C58+C68+C77+C88+C97+C107+C115+C126+C136+C146+C158 -> 29298 | D26: =D28+D37+D45+D58+D68+D77+D88+D97+D107+D115+D126+D136+D146+D158 -> 4741.72 | E26: =E28+E37+E45+E58+E68+E77+E88+E97+E107+E115+E126+E136+E146+E158 -> 24556.28 | H26: Si quieres incluir mas gastos en una celda, por el mismo dia, ingresa "=" y sigue la ecuación, por ejemplo:. = 25 + 20.5
B28: =Categorias!B24 -> ALIMENTOS Y BEBIDAS | C28: =SUM(C29:C35) -> 2000 | D28: =SUM(D29:D35) -> 1034 | E28: =SUM(E29:E35) -> 966 | H28: 1 | I28: 2 | J28: 3 | K28: 4 | L28: 5 | M28: 6 | N28: 7 | O28: 8 | P28: 9 | Q28: 10 | R28: 11 | S28: 12 | T28: 13 | U28: 14 | V28: 15 | W28: 16 | X28: 17 | Y28: 18 | Z28: 19 | AA28: 20 | AB28: 21 | AC28: 22 | AD28: 23 | AE28: 24 | AF28: 25 | AG28: 26 | AH28: 27 | AI28: 28 | AJ28: 29 | AK28: 30 | AL28: 31
B29: =Categorias!B25 -> Restaurantes | C29: 500 | D29: =SUM(Febrero!$H29:$AL29) -> 374 | E29: =C29-D29 -> 126 | L29: 374
B30: =Categorias!B26 -> Comida Carlos | C30: 500 | D30: =SUM(Febrero!$H30:$AL30) -> 370 | E30: =C30-D30 -> 130 | T30: 40 | U30: 280 | V30: 50
B31: =Categorias!B27 -> - | C31: 500 | D31: =SUM(Febrero!$H31:$AL31) -> 0 | E31: =C31-D31 -> 500
B32: =Categorias!B28 -> - | C32: 500 | D32: =SUM(Febrero!$H32:$AL32) -> 0 | E32: =C32-D32 -> 500
B33: =Categorias!B29 -> - | C33: 0 | D33: =SUM(Febrero!$H33:$AL33) -> 290 | E33: =C33-D33 -> -290 | X33: 150 | Y33: 100 | Z33: 40
B34: =Categorias!B30 -> - | C34: 0 | D34: =SUM(Febrero!$H34:$AL34) -> 0 | E34: =C34-D34 -> 0
B35: =Categorias!B31 -> - | C35: 0 | D35: =SUM(Febrero!$H35:$AL35) -> 0 | E35: =C35-D35 -> 0
B37: =Categorias!B33 -> SALUD | C37: =SUM(C38:C43) -> 6000 | D37: =SUM(D38:D43) -> 428.4 | E37: =SUM(E38:E43) -> 5571.6 | H37: 1 | I37: 2 | J37: 3 | K37: 4 | L37: 5 | M37: 6 | N37: 7 | O37: 8 | P37: 9 | Q37: 10 | R37: 11 | S37: 12 | T37: 13 | U37: 14 | V37: 15 | W37: 16 | X37: 17 | Y37: 18 | Z37: 19 | AA37: 20 | AB37: 21 | AC37: 22 | AD37: 23 | AE37: 24 | AF37: 25 | AG37: 26 | AH37: 27 | AI37: 28 | AJ37: 29 | AK37: 30 | AL37: 31
B38: =Categorias!B34 -> Gastos en médicos | C38: 5000 | D38: =SUM(Febrero!$H38:$AL38) -> 0 | E38: =C38-D38 -> 5000
B39: =Categorias!B35 -> Medicamentos | C39: 1000 | D39: =SUM(Febrero!$H39:$AL39) -> 428.4 | E39: =C39-D39 -> 571.6 | L39: 428.4
B40: =Categorias!B36 -> Dentista Kary | C40: 0 | D40: =SUM(Febrero!$H40:$AL40) -> 0 | E40: =C40-D40 -> 0
B41: =Categorias!B37 -> Dentista Thiago | C41: 0 | D41: =SUM(Febrero!$H41:$AL41) -> 0 | E41: =C41-D41 -> 0
B42: =Categorias!B38 -> - | C42: 0 | D42: =SUM(Febrero!$H42:$AL42) -> 0 | E42: =C42-D42 -> 0
B43: =Categorias!B39 -> - | C43: 0 | D43: =SUM(Febrero!$H43:$AL43) -> 0 | E43: =C43-D43 -> 0
B45: =Categorias!B41 -> CASA | C45: =SUM(C46:C56) -> 2900 | D45: =SUM(D46:D56) -> 40 | E45: =SUM(E46:E56) -> 2860 | H45: 1 | I45: 2 | J45: 3 | K45: 4 | L45: 5 | M45: 6 | N45: 7 | O45: 8 | P45: 9 | Q45: 10 | R45: 11 | S45: 12 | T45: 13 | U45: 14 | V45: 15 | W45: 16 | X45: 17 | Y45: 18 | Z45: 19 | AA45: 20 | AB45: 21 | AC45: 22 | AD45: 23 | AE45: 24 | AF45: 25 | AG45: 26 | AH45: 27 | AI45: 28 | AJ45: 29 | AK45: 30 | AL45: 31
B46: =Categorias!B42 -> Reparación | C46: 500 | D46: =SUM(Febrero!$H46:$AL46) -> 40 | E46: =C46-D46 -> 460 | S46: 40
B47: =Categorias!B43 -> Electricidad | C47: 0 | D47: =SUM(Febrero!$H47:$AL47) -> 0 | E47: =C47-D47 -> 0
B48: =Categorias!B44 -> Gas | C48: 200 | D48: =SUM(Febrero!$H48:$AL48) -> 0 | E48: =C48-D48 -> 200
B49: =Categorias!B45 -> Casa Claudia | C49: 0 | D49: =SUM(Febrero!$H49:$AL49) -> 0 | E49: =C49-D49 -> 0
B50: =Categorias!B46 -> Muebles/electrodomésticos | C50: 0 | D50: =SUM(Febrero!$H50:$AL50) -> 0 | E50: =C50-D50 -> 0
...

Sheet Marzo
B2: Presupuesto | C2: 44256
C4: Para crear un presupuesto: - A principios de este mes, rellene los campos en amarillo, despues de forma regular registre los gastos de cada dia en la tabla a la derecha - Todos los otros datos se convertirá automáticamente
C5: Fuente: | D5: =HYPERLINK("http://www.aprendizfinanciero.com/","http://www.aprendizfinanciero.com") -> http://www.aprendizfinanciero.com
B6: Ingresos
B8: Categoría | C8: Ingresos previstos | D8: Ingresos reales | E8: Diferencia | F8: Notas
B9: SUMA | C9: =C11 -> 62000 | D9: =D11 -> 51000 | E9: =E11 -> -11000
B11: =Categorias!B11 -> INGRESOS TOTALES | C11: =SUM(C12:C20) -> 62000 | D11: =SUM(D12:D20) -> 51000 | E11: =SUM(E12:E20) -> -11000 | H11: 1 | I11: 2 | J11: 3 | K11: 4 | L11: 5 | M11: 6 | N11: 7 | O11: 8 | P11: 9 | Q11: 10 | R11: 11 | S11: 12 | T11: 13 | U11: 14 | V11: 15 | W11: 16 | X11: 17 | Y11: 18 | Z11: 19 | AA11: 20 | AB11: 21 | AC11: 22 | AD11: 23 | AE11: 24 | AF11: 25 | AG11: 26 | AH11: 27 | AI11: 28 | AJ11: 29 | AK11: 30 | AL11: 31
B12: =Categorias!B12 -> Nomina | C12: 52000 | D12: =SUM(Marzo!$H12:$AL12) -> 51000 | E12: =D12-C12 -> -1000 | V12: 21000 | AL12: 30000
B13: =Categorias!B13 -> Aguinaldo | C13: 10000 | D13: =SUM(Marzo!$H13:$AL13) -> 0 | E13: =D13-C13 -> -10000
B14: =Categorias!B14 -> Fondo de ahorro | C14: 0 | D14: =SUM(Marzo!$H14:$AL14) -> 0 | E14: =D14-C14 -> 0
B15: =Categorias!B15 -> Vales despensa | C15: 0 | D15: =SUM(Marzo!$H15:$AL15) -> 0 | E15: =D15-C15 -> 0
B16: =Categorias!B16 -> Vales comedor | C16: 0 | D16: =SUM(Marzo!$H16:$AL16) -> 0 | E16: =D16-C16 -> 0
B17: =Categorias!B17 -> - | C17: 0 | D17: =SUM(Marzo!$H17:$AL17) -> 0 | E17: =D17-C17 -> 0
B18: =Categorias!B18 -> - | C18: 0 | D18: =SUM(Marzo!$H18:$AL18) -> 0 | E18: =D18-C18 -> 0
B19: =Categorias!B19 -> - | C19: 0 | D19: =SUM(Marzo!$H19:$AL19) -> 0 | E19: =D19-C19 -> 0
B20: =Categorias!B20 -> - | C20: 0 | D20: =SUM(Marzo!$H20:$AL20) -> 0 | E20: =D20-C20 -> 0
B23: Gastos | H23: Registre de gastos diarios
B25: Categoría | C25: Gastos previstos | D25: Gastos reales | E25: Diferencia | F25: Notas | H25: Los campos siguientes son para un registro diario de gastos en cada categoría.
B26: SUMA | C26: =C28+C37+C45+C58+C68+C77+C88+C97+C107+C115+C126+C136+C146+C158 -> 27988 | D26: =D28+D37+D45+D58+D68+D77+D88+D97+D107+D115+D126+D136+D146+D158 -> 28329 | E26: =E28+E37+E45+E58+E68+E77+E88+E97+E107+E115+E126+E136+E146+E158 -> -341 | H26: Si quieres incluir mas gastos en una celda, por el mismo dia, ingresa "=" y sigue la ecuación, por ejemplo:. = 25 + 20.5
B28: =Categorias!B24 -> ALIMENTOS Y BEBIDAS | C28: =SUM(C29:C35) -> 3000 | D28: =SUM(D29:D35) -> 4484 | E28: =SUM(E29:E35) -> -1484 | H28: 1 | I28: 2 | J28: 3 | K28: 4 | L28: 5 | M28: 6 | N28: 7 | O28: 8 | P28: 9 | Q28: 10 | R28: 11 | S28: 12 | T28: 13 | U28: 14 | V28: 15 | W28: 16 | X28: 17 | Y28: 18 | Z28: 19 | AA28: 20 | AB28: 21 | AC28: 22 | AD28: 23 | AE28: 24 | AF28: 25 | AG28: 26 | AH28: 27 | AI28: 28 | AJ28: 29 | AK28: 30 | AL28: 31
B29: =Categorias!B25 -> Restaurantes | C29: 2500 | D29: =SUM(Marzo!$H29:$AL29) -> 4054 | E29: =C29-D29 -> -1554 | I29: 210 | K29: 1200 | V29: 760 | Y29: 1304 | AA29: 580
B30: =Categorias!B26 -> Comida Carlos | C30: 500 | D30: =SUM(Marzo!$H30:$AL30) -> 430 | E30: =C30-D30 -> 70 | O30: 50 | R30: 180 | S30: 200
B31: =Categorias!B27 -> - | C31: 0 | D31: =SUM(Marzo!$H31:$AL31) -> 0 | E31: =C31-D31 -> 0
B32: =Categorias!B28 -> - | C32: 0 | D32: =SUM(Marzo!$H32:$AL32) -> 0 | E32: =C32-D32 -> 0
B33: =Categorias!B29 -> - | C33: 0 | D33: =SUM(Marzo!$H33:$AL33) -> 0 | E33: =C33-D33 -> 0
B34: =Categorias!B30 -> - | C34: 0 | D34: =SUM(Marzo!$H34:$AL34) -> 0 | E34: =C34-D34 -> 0
B35: =Categorias!B31 -> - | C35: 0 | D35: =SUM(Marzo!$H35:$AL35) -> 0 | E35: =C35-D35 -> 0
B37: =Categorias!B33 -> SALUD | C37: =SUM(C38:C43) -> 0 | D37: =SUM(D38:D43) -> 2492 | E37: =SUM(E38:E43) -> -2492 | H37: 1 | I37: 2 | J37: 3 | K37: 4 | L37: 5 | M37: 6 | N37: 7 | O37: 8 | P37: 9 | Q37: 10 | R37: 11 | S37: 12 | T37: 13 | U37: 14 | V37: 15 | W37: 16 | X37: 17 | Y37: 18 | Z37: 19 | AA37: 20 | AB37: 21 | AC37: 22 | AD37: 23 | AE37: 24 | AF37: 25 | AG37: 26 | AH37: 27 | AI37: 28 | AJ37: 29 | AK37: 30 | AL37: 31
B38: =Categorias!B34 -> Gastos en médicos | C38: 0 | D38: =SUM(Marzo!$H38:$AL38) -> 0 | E38: =C38-D38 -> 0
B39: =Categorias!B35 -> Medicamentos | C39: 0 | D39: =SUM(Marzo!$H39:$AL39) -> 2492 | E39: =C39-D39 -> -2492 | O39: 570 | P39: 1372 | V39: 190 | W39: 360
B40: =Categorias!B36 -> Dentista Kary | C40: 0 | D40: =SUM(Marzo!$H40:$AL40) -> 0 | E40: =C40-D40 -> 0
B41: =Categorias!B37 -> Dentista Thiago | C41: 0 | D41: =SUM(Marzo!$H41:$AL41) -> 0 | E41: =C41-D41 -> 0
B42: =Categorias!B38 -> - | C42: 0 | D42: =SUM(Marzo!$H42:$AL42) -> 0 | E42: =C42-D42 -> 0
B43: =Categorias!B39 -> - | C43: 0 | D43: =SUM(Marzo!$H43:$AL43) -> 0 | E43: =C43-D43 -> 0
B45: =Categorias!B41 -> CASA | C45: =SUM(C46:C56) -> 14400 | D45: =SUM(D46:D56) -> 16730 | E45: =SUM(E46:E56) -> -2330 | H45: 1 | I45: 2 | J45: 3 | K45: 4 | L45: 5 | M45: 6 | N45: 7 | O45: 8 | P45: 9 | Q45: 10 | R45: 11 | S45: 12 | T45: 13 | U45: 14 | V45: 15 | W45: 16 | X45: 17 | Y45: 18 | Z45: 19 | AA45: 20 | AB45: 21 | AC45: 22 | AD45: 23 | AE45: 24 | AF45: 25 | AG45: 26 | AH45: 27 | AI45: 28 | AJ45: 29 | AK45: 30 | AL45: 31
B46: =Categorias!B42 -> Reparación | C46: 0 | D46: =SUM(Marzo!$H46:$AL46) -> 8730 | E46: =C46-D46 -> -8730 | I46: 7500 | AL46: 1230
B47: =Categorias!B43 -> Electricidad | C47: 1200 | D47: =SUM(Marzo!$H47:$AL47) -> 0 | E47: =C47-D47 -> 1200
B48: =Categorias!B44 -> Gas | C48: 200 | D48: =SUM(Marzo!$H48:$AL48) -> 0 | E48: =C48-D48 -> 200
B49: =Categorias!B45 -> Casa Claudia | C49: 0 | D49: =SUM(Marzo!$H49:$AL49) -> 0 | E49: =C49-D49 -> 0
B50: =Categorias!B46 -> Muebles/electrodomésticos | C50: 0 | D50: =SUM(Marzo!$H50:$AL50) -> 0 | E50: =C50-D50 -> 0
...

Sheet Abril
B2: Presupuesto | C2: 44287
C4: Para crear un presupuesto: - A principios de este mes, rellene los campos en amarillo, despues de forma regular registre los gastos de cada dia en la tabla a la derecha - Todos los otros datos se convertirá automáticamente
C5: Fuente: | D5: =HYPERLINK("http://www.aprendizfinanciero.com/","http://www.aprendizfinanciero.com") -> http://www.aprendizfinanciero.com
B6: Ingresos
B8: Categoría | C8: Ingresos previstos | D8: Ingresos reales | E8: Diferencia | F8: Notas
B9: SUMA | C9: =C11 -> 0 | D9: =D11 -> 52000 | E9: =E11 -> 52000
B11: =Categorias!B11 -> INGRESOS TOTALES | C11: =SUM(C12:C20) -> 0 | D11: =SUM(D12:D20) -> 52000 | E11: =SUM(E12:E20) -> 52000 | H11: 1 | I11: 2 | J11: 3 | K11: 4 | L11: 5 | M11: 6 | N11: 7 | O11: 8 | P11: 9 | Q11: 10 | R11: 11 | S11: 12 | T11: 13 | U11: 14 | V11: 15 | W11: 16 | X11: 17 | Y11: 18 | Z11: 19 | AA11: 20 | AB11: 21 | AC11: 22 | AD11: 23 | AE11: 24 | AF11: 25 | AG11: 26 | AH11: 27 | AI11: 28 | AJ11: 29 | AK11: 30 | AL11: 31
B12: =Categorias!B12 -> Nomina | C12: 0 | D12: =SUM(Abril!$H12:$AL12) -> 42000 | E12: =D12-C12 -> 42000 | V12: 21000 | AL12: 21000
B13: =Categorias!B13 -> Aguinaldo | C13: 0 | D13: =SUM(Abril!$H13:$AL13) -> 10000 | E13: =D13-C13 -> 10000 | AL13: 10000
B14: =Categorias!B14 -> Fondo de ahorro | C14: 0 | D14: =SUM(Abril!$H14:$AL14) -> 0 | E14: =D14-C14 -> 0
B15: =Categorias!B15 -> Vales despensa | C15: 0 | D15: =SUM(Abril!$H15:$AL15) -> 0 | E15: =D15-C15 -> 0
B16: =Categorias!B16 -> Vales comedor | C16: 0 | D16: =SUM(Abril!$H16:$AL16) -> 0 | E16: =D16-C16 -> 0
B17: =Categorias!B17 -> - | C17: 0 | D17: =SUM(Abril!$H17:$AL17) -> 0 | E17: =D17-C17 -> 0
B18: =Categorias!B18 -> - | C18: 0 | D18: =SUM(Abril!$H18:$AL18) -> 0 | E18: =D18-C18 -> 0
B19: =Categorias!B19 -> - | C19: 0 | D19: =SUM(Abril!$H19:$AL19) -> 0 | E19: =D19-C19 -> 0
B20: =Categorias!B20 -> - | C20: 0 | D20: =SUM(Abril!$H20:$AL20) -> 0 | E20: =D20-C20 -> 0
B23: Gastos | H23: Registre de gastos diarios
B25: Categoría | C25: Gastos previstos | D25: Gastos reales | E25: Diferencia | F25: Notas | H25: Los campos siguientes son para un registro diario de gastos en cada categoría.
B26: SUMA | C26: =C28+C37+C45+C58+C68+C77+C88+C97+C107+C115+C126+C136+C146+C158 -> 0 | D26: =D28+D37+D45+D58+D68+D77+D88+D97+D107+D115+D126+D136+D146+D158 -> 25574 | E26: =E28+E37+E45+E58+E68+E77+E88+E97+E107+E115+E126+E136+E146+E158 -> -25574 | H26: Si quieres incluir mas gastos en una celda, por el mismo dia, ingresa "=" y sigue la ecuación, por ejemplo:. = 25 + 20.5
B28: =Categorias!B24 -> ALIMENTOS Y BEBIDAS | C28: =SUM(C29:C35) -> 0 | D28: =SUM(D29:D35) -> 2602 | E28: =SUM(E29:E35) -> -2602 | H28: 1 | I28: 2 | J28: 3 | K28: 4 | L28: 5 | M28: 6 | N28: 7 | O28: 8 | P28: 9 | Q28: 10 | R28: 11 | S28: 12 | T28: 13 | U28: 14 | V28: 15 | W28: 16 | X28: 17 | Y28: 18 | Z28: 19 | AA28: 20 | AB28: 21 | AC28: 22 | AD28: 23 | AE28: 24 | AF28: 25 | AG28: 26 | AH28: 27 | AI28: 28 | AJ28: 29 | AK28: 30 | AL28: 31
B29: =Categorias!B25 -> Restaurantes | C29: 0 | D29: =SUM(Abril!$H29:$AL29) -> 2015 | E29: =C29-D29 -> -2015 | I29: 1029 | L29: 40 | M29: 218 | N29: 60 | Q29: 555 | AD29: 33 | AG29: 80
B30: =Categorias!B26 -> Comida Carlos | C30: 0 | D30: =SUM(Abril!$H30:$AL30) -> 587 | E30: =C30-D30 -> -587 | AA30: 287 | AK30: 300
B31: =Categorias!B27 -> - | C31: 0 | D31: =SUM(Abril!$H31:$AL31) -> 0 | E31: =C31-D31 -> 0
B32: =Categorias!B28 -> - | C32: 0 | D32: =SUM(Abril!$H32:$AL32) -> 0 | E32: =C32-D32 -> 0
B33: =Categorias!B29 -> - | C33: 0 | D33: =SUM(Abril!$H33:$AL33) -> 0 | E33: =C33-D33 -> 0
B34: =Categorias!B30 -> - | C34: 0 | D34: =SUM(Abril!$H34:$AL34) -> 0 | E34: =C34-D34 -> 0
B35: =Categorias!B31 -> - | C35: 0 | D35: =SUM(Abril!$H35:$AL35) -> 0 | E35: =C35-D35 -> 0
B37: =Categorias!B33 -> SALUD | C37: =SUM(C38:C43) -> 0 | D37: =SUM(D38:D43) -> 4070 | E37: =SUM(E38:E43) -> -4070 | H37: 1 | I37: 2 | J37: 3 | K37: 4 | L37: 5 | M37: 6 | N37: 7 | O37: 8 | P37: 9 | Q37: 10 | R37: 11 | S37: 12 | T37: 13 | U37: 14 | V37: 15 | W37: 16 | X37: 17 | Y37: 18 | Z37: 19 | AA37: 20 | AB37: 21 | AC37: 22 | AD37: 23 | AE37: 24 | AF37: 25 | AG37: 26 | AH37: 27 | AI37: 28 | AJ37: 29 | AK37: 30 | AL37: 31
B38: =Categorias!B34 -> Gastos en médicos | C38: 0 | D38: =SUM(Abril!$H38:$AL38) -> 2400 | E38: =C38-D38 -> -2400 | AD38: 2400
B39: =Categorias!B35 -> Medicamentos | C39: 0 | D39: =SUM(Abril!$H39:$AL39) -> 1670 | E39: =C39-D39 -> -1670 | Y39: 470 | AC39: 950 | AD39: 250
B40: =Categorias!B36 -> Dentista Kary | C40: 0 | D40: =SUM(Abril!$H40:$AL40) -> 0 | E40: =C40-D40 -> 0
B41: =Categorias!B37 -> Dentista Thiago | C41: 0 | D41: =SUM(Abril!$H41:$AL41) -> 0 | E41: =C41-D41 -> 0
B42: =Categorias!B38 -> - | C42: 0 | D42: =SUM(Abril!$H42:$AL42) -> 0 | E42: =C42-D42 -> 0
B43: =Categorias!B39 -> - | C43: 0 | D43: =SUM(Abril!$H43:$AL43) -> 0 | E43: =C43-D43 -> 0
B45: =Categorias!B41 -> CASA | C45: =SUM(C46:C56) -> 0 | D45: =SUM(D46:D56) -> 12559 | E45: =SUM(E46:E56) -> -12559 | H45: 1 | I45: 2 | J45: 3 | K45: 4 | L45: 5 | M45: 6 | N45: 7 | O45: 8 | P45: 9 | Q45: 10 | R45: 11 | S45: 12 | T45: 13 | U45: 14 | V45: 15 | W45: 16 | X45: 17 | Y45: 18 | Z45: 19 | AA45: 20 | AB45: 21 | AC45: 22 | AD45: 23 | AE45: 24 | AF45: 25 | AG45: 26 | AH45: 27 | AI45: 28 | AJ45: 29 | AK45: 30 | AL45: 31
B46: =Categorias!B42 -> Reparación | C46: 0 | D46: =SUM(Abril!$H46:$AL46) -> 12236 | E46: =C46-D46 -> -12236 | H46: 2645 | I46: 591 | K46: 200 | L46: 8000 | O46: 800
B47: =Categorias!B43 -> Electricidad | C47: 0 | D47: =SUM(Abril!$H47:$AL47) -> 0 | E47: =C47-D47 -> 0
B48: =Categorias!B44 -> Gas | C48: 0 | D48: =SUM(Abril!$H48:$AL48) -> 200 | E48: =C48-D48 -> -200 | K48: 200
B49: =Categorias!B45 -> Casa Claudia | C49: 0 | D49: =SUM(Abril!$H49:$AL49) -> 123 | E49: =C49-D49 -> -123 | L49: 123
B50: =Categorias!B46 -> Muebles/electrodomésticos | C50: 0 | D50: =SUM(Abril!$H50:$AL50) -> 0 | E50: =C50-D50 -> 0
...

Sheet Mayo
B2: Presupuesto | C2: 44317
C4: Para crear un presupuesto: - A principios de este mes, rellene los campos en amarillo, despues de forma regular registre los gastos de cada dia en la tabla a la derecha - Todos los otros datos se convertirá automáticamente
C5: Fuente: | D5: =HYPERLINK("http://www.aprendizfinanciero.com/","http://www.aprendizfinanciero.com") -> http://www.aprendizfinanciero.com
B6: Ingresos
B8: Categoría | C8: Ingresos previstos | D8: Ingresos reales | E8: Diferencia | F8: Notas
B9: SUMA | C9: =C11 -> 41720.4 | D9: =D11 -> 42720.4 | E9: =E11 -> 1000
B11: =Categorias!B11 -> INGRESOS TOTALES | C11: =SUM(C12:C20) -> 41720.4 | D11: =SUM(D12:D20) -> 42720.4 | E11: =SUM(E12:E20) -> 1000 | H11: 1 | I11: 2 | J11: 3 | K11: 4 | L11: 5 | M11: 6 | N11: 7 | O11: 8 | P11: 9 | Q11: 10 | R11: 11 | S11: 12 | T11: 13 | U11: 14 | V11: 15 | W11: 16 | X11: 17 | Y11: 18 | Z11: 19 | AA11: 20 | AB11: 21 | AC11: 22 | AD11: 23 | AE11: 24 | AF11: 25 | AG11: 26 | AH11: 27 | AI11: 28 | AJ11: 29 | AK11: 30 | AL11: 31
B12: =Categorias!B12 -> Nomina | C12: 41720.4 | D12: =SUM(Mayo!$H12:$AL12) -> 42720.4 | E12: =D12-C12 -> 1000 | T12: 20860.2 | AL12: 21860.2
B13: =Categorias!B13 -> Aguinaldo | C13: 0 | D13: =SUM(Mayo!$H13:$AL13) -> 0 | E13: =D13-C13 -> 0
B14: =Categorias!B14 -> Fondo de ahorro | C14: 0 | D14: =SUM(Mayo!$H14:$AL14) -> 0 | E14: =D14-C14 -> 0
B15: =Categorias!B15 -> Vales despensa | C15: 0 | D15: =SUM(Mayo!$H15:$AL15) -> 0 | E15: =D15-C15 -> 0
B16: =Categorias!B16 -> Vales comedor | C16: 0 | D16: =SUM(Mayo!$H16:$AL16) -> 0 | E16: =D16-C16 -> 0
B17: =Categorias!B17 -> - | C17: 0 | D17: =SUM(Mayo!$H17:$AL17) -> 0 | E17: =D17-C17 -> 0
B18: =Categorias!B18 -> - | C18: 0 | D18: =SUM(Mayo!$H18:$AL18) -> 0 | E18: =D18-C18 -> 0
B19: =Categorias!B19 -> - | C19: 0 | D19: =SUM(Mayo!$H19:$AL19) -> 0 | E19: =D19-C19 -> 0
B20: =Categorias!B20 -> - | C20: 0 | D20: =SUM(Mayo!$H20:$AL20) -> 0 | E20: =D20-C20 -> 0
B23: Gastos | H23: Registre de gastos diarios
B25: Categoría | C25: Gastos previstos | D25: Gastos reales | E25: Diferencia | F25: Notas | H25: Los campos siguientes son para un registro diario de gastos en cada categoría.
B26: SUMA | C26: =C28+C37+C45+C58+C68+C77+C88+C97+C107+C115+C126+C136+C146+C158 -> 24954.85 | D26: =D28+D37+D45+D58+D68+D77+D88+D97+D107+D115+D126+D136+D146+D158 -> 26612 | E26: =E28+E37+E45+E58+E68+E77+E88+E97+E107+E115+E126+E136+E146+E158 -> -1657.15 | H26: Si quieres incluir mas gastos en una celda, por el mismo dia, ingresa "=" y sigue la ecuación, por ejemplo:. = 25 + 20.5
B28: =Categorias!B24 -> ALIMENTOS Y BEBIDAS | C28: =SUM(C29:C35) -> 2000 | D28: =SUM(D29:D35) -> 1898 | E28: =SUM(E29:E35) -> 102 | H28: 1 | I28: 2 | J28: 3 | K28: 4 | L28: 5 | M28: 6 | N28: 7 | O28: 8 | P28: 9 | Q28: 10 | R28: 11 | S28: 12 | T28: 13 | U28: 14 | V28: 15 | W28: 16 | X28: 17 | Y28: 18 | Z28: 19 | AA28: 20 | AB28: 21 | AC28: 22 | AD28: 23 | AE28: 24 | AF28: 25 | AG28: 26 | AH28: 27 | AI28: 28 | AJ28: 29 | AK28: 30 | AL28: 31
B29: =Categorias!B25 -> Restaurantes | C29: 2000 | D29: =SUM(Mayo!$H29:$AL29) -> 1380 | E29: =C29-D29 -> 620 | H29: 380 | P29: 1000
B30: =Categorias!B26 -> Comida Carlos | C30: 0 | D30: =SUM(Mayo!$H30:$AL30) -> 518 | E30: =C30-D30 -> -518 | P30: 310 | Q30: 16 | T30: 66 | W30: 126
B31: =Categorias!B27 -> - | C31: 0 | D31: =SUM(Mayo!$H31:$AL31) -> 0 | E31: =C31-D31 -> 0
B32: =Categorias!B28 -> - | C32: 0 | D32: =SUM(Mayo!$H32:$AL32) -> 0 | E32: =C32-D32 -> 0
B33: =Categorias!B29 -> - | C33: 0 | D33: =SUM(Mayo!$H33:$AL33) -> 0 | E33: =C33-D33 -> 0
B34: =Categorias!B30 -> - | C34: 0 | D34: =SUM(Mayo!$H34:$AL34) -> 0 | E34: =C34-D34 -> 0
B35: =Categorias!B31 -> - | C35: 0 | D35: =SUM(Mayo!$H35:$AL35) -> 0 | E35: =C35-D35 -> 0
B37: =Categorias!B33 -> SALUD | C37: =SUM(C38:C43) -> 600 | D37: =SUM(D38:D43) -> 1055 | E37: =SUM(E38:E43) -> -455 | H37: 1 | I37: 2 | J37: 3 | K37: 4 | L37: 5 | M37: 6 | N37: 7 | O37: 8 | P37: 9 | Q37: 10 | R37: 11 | S37: 12 | T37: 13 | U37: 14 | V37: 15 | W37: 16 | X37: 17 | Y37: 18 | Z37: 19 | AA37: 20 | AB37: 21 | AC37: 22 | AD37: 23 | AE37: 24 | AF37: 25 | AG37: 26 | AH37: 27 | AI37: 28 | AJ37: 29 | AK37: 30 | AL37: 31
B38: =Categorias!B34 -> Gastos en médicos | C38: 0 | D38: =SUM(Mayo!$H38:$AL38) -> 170 | E38: =C38-D38 -> -170 | AB38: 170
B39: =Categorias!B35 -> Medicamentos | C39: 0 | D39: =SUM(Mayo!$H39:$AL39) -> 885 | E39: =C39-D39 -> -885 | H39: 600 | J39: 285
B40: =Categorias!B36 -> Dentista Kary | C40: 600 | D40: =SUM(Mayo!$H40:$AL40) -> 0 | E40: =C40-D40 -> 600
B41: =Categorias!B37 -> Dentista Thiago | C41: 0 | D41: =SUM(Mayo!$H41:$AL41) -> 0 | E41: =C41-D41 -> 0
B42: =Categorias!B38 -> - | C42: 0 | D42: =SUM(Mayo!$H42:$AL42) -> 0 | E42: =C42-D42 -> 0
B43: =Categorias!B39 -> - | C43: 0 | D43: =SUM(Mayo!$H43:$AL43) -> 0 | E43: =C43-D43 -> 0
B45: =Categorias!B41 -> CASA | C45: =SUM(C46:C56) -> 8400 | D45: =SUM(D46:D56) -> 1510 | E45: =SUM(E46:E56) -> 6890 | H45: 1 | I45: 2 | J45: 3 | K45: 4 | L45: 5 | M45: 6 | N45: 7 | O45: 8 | P45: 9 | Q45: 10 | R45: 11 | S45: 12 | T45: 13 | U45: 14 | V45: 15 | W45: 16 | X45: 17 | Y45: 18 | Z45: 19 | AA45: 20 | AB45: 21 | AC45: 22 | AD45: 23 | AE45: 24 | AF45: 25 | AG45: 26 | AH45: 27 | AI45: 28 | AJ45: 29 | AK45: 30 | AL45: 31
B46: =Categorias!B42 -> Reparación | C46: 0 | D46: =SUM(Mayo!$H46:$AL46) -> 1510 | E46: =C46-D46 -> -1510 | N46: 1510
B47: =Categorias!B43 -> Electricidad | C47: 1000 | D47: =SUM(Mayo!$H47:$AL47) -> 0 | E47: =C47-D47 -> 1000
B48: =Categorias!B44 -> Gas | C48: 300 | D48: =SUM(Mayo!$H48:$AL48) -> 0 | E48: =C48-D48 -> 300
B49: =Categorias!B45 -> Casa Claudia | C49: 100 | D49: =SUM(Mayo!$H49:$AL49) -> 0 | E49: =C49-D49 -> 100
B50: =Categorias!B46 -> Muebles/electrodomésticos | C50: 0 | D50: =SUM(Mayo!$H50:$AL50) -> 0 | E50: =C50-D50 -> 0
...

Sheet Junio
B2: Presupuesto | C2: 44348
C4: Para crear un presupuesto: - A principios de este mes, rellene los campos en amarillo, despues de forma regular registre los gastos de cada dia en la tabla a la derecha - Todos los otros datos se convertirá automáticamente
C5: Fuente: | D5: =HYPERLINK("http://www.aprendizfinanciero.com/","http://www.aprendizfinanciero.com") -> http://www.aprendizfinanciero.com
B6: Ingresos
B8: Categoría | C8: Ingresos previstos | D8: Ingresos reales | E8: Diferencia | F8: Notas
B9: SUMA | C9: =C11 -> 41720.4 | D9: =D11 -> 41720.4 | E9: =E11 -> 0
B11: =Categorias!B11 -> INGRESOS TOTALES | C11: =SUM(C12:C20) -> 41720.4 | D11: =SUM(D12:D20) -> 41720.4 | E11: =SUM(E12:E20) -> 0 | H11: 1 | I11: 2 | J11: 3 | K11: 4 | L11: 5 | M11: 6 | N11: 7 | O11: 8 | P11: 9 | Q11: 10 | R11: 11 | S11: 12 | T11: 13 | U11: 14 | V11: 15 | W11: 16 | X11: 17 | Y11: 18 | Z11: 19 | AA11: 20 | AB11: 21 | AC11: 22 | AD11: 23 | AE11: 24 | AF11: 25 | AG11: 26 | AH11: 27 | AI11: 28 | AJ11: 29 | AK11: 30 | AL11: 31
B12: =Categorias!B12 -> Nomina | C12: 41720.4 | D12: =SUM(Junio!$H12:$AL12) -> 41720.4 | E12: =D12-C12 -> 0 | V12: 20860.2 | AK12: 20860.2
B13: =Categorias!B13 -> Aguinaldo | C13: 0 | D13: =SUM(Junio!$H13:$AL13) -> 0 | E13: =D13-C13 -> 0
B14: =Categorias!B14 -> Fondo de ahorro | C14: 0 | D14: =SUM(Junio!$H14:$AL14) -> 0 | E14: =D14-C14 -> 0
B15: =Categorias!B15 -> Vales despensa | C15: 0 | D15: =SUM(Junio!$H15:$AL15) -> 0 | E15: =D15-C15 -> 0
B16: =Categorias!B16 -> Vales comedor | C16: 0 | D16: =SUM(Junio!$H16:$AL16) -> 0 | E16: =D16-C16 -> 0
B17: =Categorias!B17 -> - | C17: 0 | D17: =SUM(Junio!$H17:$AL17) -> 0 | E17: =D17-C17 -> 0
B18: =Categorias!B18 -> - | C18: 0 | D18: =SUM(Junio!$H18:$AL18) -> 0 | E18: =D18-C18 -> 0
B19: =Categorias!B19 -> - | C19: 0 | D19: =SUM(Junio!$H19:$AL19) -> 0 | E19: =D19-C19 -> 0
B20: =Categorias!B20 -> - | C20: 0 | D20: =SUM(Junio!$H20:$AL20) -> 0 | E20: =D20-C20 -> 0
B23: Gastos | H23: Registre de gastos diarios
B25: Categoría | C25: Gastos previstos | D25: Gastos reales | E25: Diferencia | F25: Notas | H25: Los campos siguientes son para un registro diario de gastos en cada categoría.
B26: SUMA | C26: =C28+C37+C45+C58+C68+C77+C88+C97+C107+C115+C126+C136+C146+C158 -> 27580.9 | D26: =D28+D37+D45+D58+D68+D77+D88+D97+D107+D115+D126+D136+D146+D158 -> 37985.34 | E26: =E28+E37+E45+E58+E68+E77+E88+E97+E107+E115+E126+E136+E146+E158 -> -10404.44 | H26: Si quieres incluir mas gastos en una celda, por el mismo dia, ingresa "=" y sigue la ecuación, por ejemplo:. = 25 + 20.5
B28: =Categorias!B24 -> ALIMENTOS Y BEBIDAS | C28: =SUM(C29:C35) -> 2000 | D28: =SUM(D29:D35) -> 3576.27 | E28: =SUM(E29:E35) -> -1576.27 | H28: 1 | I28: 2 | J28: 3 | K28: 4 | L28: 5 | M28: 6 | N28: 7 | O28: 8 | P28: 9 | Q28: 10 | R28: 11 | S28: 12 | T28: 13 | U28: 14 | V28: 15 | W28: 16 | X28: 17 | Y28: 18 | Z28: 19 | AA28: 20 | AB28: 21 | AC28: 22 | AD28: 23 | AE28: 24 | AF28: 25 | AG28: 26 | AH28: 27 | AI28: 28 | AJ28: 29 | AK28: 30 | AL28: 31
B29: =Categorias!B25 -> Restaurantes | C29: 500 | D29: =SUM(Junio!$H29:$AL29) -> 3169.27 | E29: =C29-D29 -> -2669.27 | N29: 600 | O29: 200 | S29: =140+795.27 -> 935.27 | U29: =123+28+14 -> 165 | W29: 600 | AC29: 300 | AD29: 75 | AG29: =135+159 -> 294
B30: =Categorias!B26 -> Comida Carlos | C30: 500 | D30: =SUM(Junio!$H30:$AL30) -> 407 | E30: =C30-D30 -> 93 | H30: 170 | I30: 55 | J30: 150 | AG30: 32
B31: =Categorias!B27 -> - | C31: 500 | D31: =SUM(Junio!$H31:$AL31) -> 0 | E31: =C31-D31 -> 500
B32: =Categorias!B28 -> - | C32: 500 | D32: =SUM(Junio!$H32:$AL32) -> 0 | E32: =C32-D32 -> 500
B33: =Categorias!B29 -> - | C33: 0 | D33: =SUM(Junio!$H33:$AL33) -> 0 | E33: =C33-D33 -> 0
B34: =Categorias!B30 -> - | C34: 0 | D34: =SUM(Junio!$H34:$AL34) -> 0 | E34: =C34-D34 -> 0
B35: =Categorias!B31 -> - | C35: 0 | D35: =SUM(Junio!$H35:$AL35) -> 0 | E35: =C35-D35 -> 0
B37: =Categorias!B33 -> SALUD | C37: =SUM(C38:C43) -> 1100 | D37: =SUM(D38:D43) -> 735 | E37: =SUM(E38:E43) -> 365 | H37: 1 | I37: 2 | J37: 3 | K37: 4 | L37: 5 | M37: 6 | N37: 7 | O37: 8 | P37: 9 | Q37: 10 | R37: 11 | S37: 12 | T37: 13 | U37: 14 | V37: 15 | W37: 16 | X37: 17 | Y37: 18 | Z37: 19 | AA37: 20 | AB37: 21 | AC37: 22 | AD37: 23 | AE37: 24 | AF37: 25 | AG37: 26 | AH37: 27 | AI37: 28 | AJ37: 29 | AK37: 30 | AL37: 31
B38: =Categorias!B34 -> Gastos en médicos | C38: 0 | D38: =SUM(Junio!$H38:$AL38) -> 0 | E38: =C38-D38 -> 0
B39: =Categorias!B35 -> Medicamentos | C39: 0 | D39: =SUM(Junio!$H39:$AL39) -> 235 | E39: =C39-D39 -> -235 | W39: 235
B40: =Categorias!B36 -> Dentista Kary | C40: 1100 | D40: =SUM(Junio!$H40:$AL40) -> 500 | E40: =C40-D40 -> 600 | J40: 500
B41: =Categorias!B37 -> Dentista Thiago | C41: 0 | D41: =SUM(Junio!$H41:$AL41) -> 0 | E41: =C41-D41 -> 0
B42: =Categorias!B38 -> - | C42: 0 | D42: =SUM(Junio!$H42:$AL42) -> 0 | E42: =C42-D42 -> 0
B43: =Categorias!B39 -> - | C43: 0 | D43: =SUM(Junio!$H43:$AL43) -> 0 | E43: =C43-D43 -> 0
B45: =Categorias!B41 -> CASA | C45: =SUM(C46:C56) -> 7240 | D45: =SUM(D46:D56) -> 12235 | E45: =SUM(E46:E56) -> -4995 | H45: 1 | I45: 2 | J45: 3 | K45: 4 | L45: 5 | M45: 6 | N45: 7 | O45: 8 | P45: 9 | Q45: 10 | R45: 11 | S45: 12 | T45: 13 | U45: 14 | V45: 15 | W45: 16 | X45: 17 | Y45: 18 | Z45: 19 | AA45: 20 | AB45: 21 | AC45: 22 | AD45: 23 | AE45: 24 | AF45: 25 | AG45: 26 | AH45: 27 | AI45: 28 | AJ45: 29 | AK45: 30 | AL45: 31
B46: =Categorias!B42 -> Reparación | C46: 0 | D46: =SUM(Junio!$H46:$AL46) -> 0 | E46: =C46-D46 -> 0
B47: =Categorias!B43 -> Electricidad | C47: 0 | D47: =SUM(Junio!$H47:$AL47) -> 0 | E47: =C47-D47 -> 0
B48: =Categorias!B44 -> Gas | C48: 240 | D48: =SUM(Junio!$H48:$AL48) -> 235 | E48: =C48-D48 -> 5 | H48: 235
B49: =Categorias!B45 -> Casa Claudia | C49: 0 | D49: =SUM(Junio!$H49:$AL49) -> 0 | E49: =C49-D49 -> 0
B50: =Categorias!B46 -> Muebles/electrodomésticos | C50: 0 | D50: =SUM(Junio!$H50:$AL50) -> 0 | E50: =C50-D50 -> 0
...

Sheet Julio
B2: Presupuesto | C2: 44378
C4: Para crear un presupuesto: - A principios de este mes, rellene los campos en amarillo, despues de forma regular registre los gastos de cada dia en la tabla a la derecha - Todos los otros datos se convertirá automáticamente
C5: Fuente: | D5: =HYPERLINK("http://www.aprendizfinanciero.com/","http://www.aprendizfinanciero.com") -> http://www.aprendizfinanciero.com
B6: Ingresos
B8: Categoría | C8: Ingresos previstos | D8: Ingresos reales | E8: Diferencia | F8: Notas
B9: SUMA | C9: =C11 -> 0 | D9: =D11 -> 0 | E9: =E11 -> 0
B11: =Categorias!B11 -> INGRESOS TOTALES | C11: =SUM(C12:C20) -> 0 | D11: =SUM(D12:D20) -> 0 | E11: =SUM(E12:E20) -> 0 | H11: 1 | I11: 2 | J11: 3 | K11: 4 | L11: 5 | M11: 6 | N11: 7 | O11: 8 | P11: 9 | Q11: 10 | R11: 11 | S11: 12 | T11: 13 | U11: 14 | V11: 15 | W11: 16 | X11: 17 | Y11: 18 | Z11: 19 | AA11: 20 | AB11: 21 | AC11: 22 | AD11: 23 | AE11: 24 | AF11: 25 | AG11: 26 | AH11: 27 | AI11: 28 | AJ11: 29 | AK11: 30 | AL11: 31
B12: =Categorias!B12 -> Nomina | C12: 0 | D12: =SUM(Julio!$H12:$AL12) -> 0 | E12: =D12-C12 -> 0
B13: =Categorias!B13 -> Aguinaldo | C13: 0 | D13: =SUM(Julio!$H13:$AL13) -> 0 | E13: =D13-C13 -> 0
B14: =Categorias!B14 -> Fondo de ahorro | C14: 0 | D14: =SUM(Julio!$H14:$AL14) -> 0 | E14: =D14-C14 -> 0
B15: =Categorias!B15 -> Vales despensa | C15: 0 | D15: =SUM(Julio!$H15:$AL15) -> 0 | E15: =D15-C15 -> 0
B16: =Categorias!B16 -> Vales comedor | C16: 0 | D16: =SUM(Julio!$H16:$AL16) -> 0 | E16: =D16-C16 -> 0
B17: =Categorias!B17 -> - | C17: 0 | D17: =SUM(Julio!$H17:$AL17) -> 0 | E17: =D17-C17 -> 0
B18: =Categorias!B18 -> - | C18: 0 | D18: =SUM(Julio!$H18:$AL18) -> 0 | E18: =D18-C18 -> 0
B19: =Categorias!B19 -> - | C19: 0 | D19: =SUM(Julio!$H19:$AL19) -> 0 | E19: =D19-C19 -> 0
B20: =Categorias!B20 -> - | C20: 0 | D20: =SUM(Julio!$H20:$AL20) -> 0 | E20: =D20-C20 -> 0
B23: Gastos | H23: Registre de gastos diarios
B25: Categoría | C25: Gastos previstos | D25: Gastos reales | E25: Diferencia | F25: Notas | H25: Los campos siguientes son para un registro diario de gastos en cada categoría.
B26: SUMA | C26: =C28+C37+C45+C58+C68+C77+C88+C97+C107+C115+C126+C136+C146+C158 -> 9970.7 | D26: =D28+D37+D45+D58+D68+D77+D88+D97+D107+D115+D126+D136+D146+D158 -> 12964 | E26: =E28+E37+E45+E58+E68+E77+E88+E97+E107+E115+E126+E136+E146+E158 -> -2993.3 | H26: Si quieres incluir mas gastos en una celda, por el mismo dia, ingresa "=" y sigue la ecuación, por ejemplo:. = 25 + 20.5
B28: =Categorias!B24 -> ALIMENTOS Y BEBIDAS | C28: =SUM(C29:C35) -> 0 | D28: =SUM(D29:D35) -> 3264 | E28: =SUM(E29:E35) -> -3264 | H28: 1 | I28: 2 | J28: 3 | K28: 4 | L28: 5 | M28: 6 | N28: 7 | O28: 8 | P28: 9 | Q28: 10 | R28: 11 | S28: 12 | T28: 13 | U28: 14 | V28: 15 | W28: 16 | X28: 17 | Y28: 18 | Z28: 19 | AA28: 20 | AB28: 21 | AC28: 22 | AD28: 23 | AE28: 24 | AF28: 25 | AG28: 26 | AH28: 27 | AI28: 28 | AJ28: 29 | AK28: 30 | AL28: 31
B29: =Categorias!B25 -> Restaurantes | C29: 0 | D29: =SUM(Julio!$H29:$AL29) -> 2804 | E29: =C29-D29 -> -2804 | H29: 285 | J29: 1448 | L29: 199 | M29: 300 | O29: 300 | AB29: 272
B30: =Categorias!B26 -> Comida Carlos | C30: 0 | D30: =SUM(Julio!$H30:$AL30) -> 370 | E30: =C30-D30 -> -370 | I30: 370
B31: =Categorias!B27 -> - | C31: 0 | D31: =SUM(Julio!$H31:$AL31) -> 0 | E31: =C31-D31 -> 0
B32: =Categorias!B28 -> - | C32: 0 | D32: =SUM(Julio!$H32:$AL32) -> 90 | E32: =C32-D32 -> -90 | H32: 90
B33: =Categorias!B29 -> - | C33: 0 | D33: =SUM(Julio!$H33:$AL33) -> 0 | E33: =C33-D33 -> 0
B34: =Categorias!B30 -> - | C34: 0 | D34: =SUM(Julio!$H34:$AL34) -> 0 | E34: =C34-D34 -> 0
B35: =Categorias!B31 -> - | C35: 0 | D35: =SUM(Julio!$H35:$AL35) -> 0 | E35: =C35-D35 -> 0
B37: =Categorias!B33 -> SALUD | C37: =SUM(C38:C43) -> 0 | D37: =SUM(D38:D43) -> 0 | E37: =SUM(E38:E43) -> 0 | H37: 1 | I37: 2 | J37: 3 | K37: 4 | L37: 5 | M37: 6 | N37: 7 | O37: 8 | P37: 9 | Q37: 10 | R37: 11 | S37: 12 | T37: 13 | U37: 14 | V37: 15 | W37: 16 | X37: 17 | Y37: 18 | Z37: 19 | AA37: 20 | AB37: 21 | AC37: 22 | AD37: 23 | AE37: 24 | AF37: 25 | AG37: 26 | AH37: 27 | AI37: 28 | AJ37: 29 | AK37: 30 | AL37: 31
B38: =Categorias!B34 -> Gastos en médicos | C38: 0 | D38: =SUM(Julio!$H38:$AL38) -> 0 | E38: =C38-D38 -> 0
B39: =Categorias!B35 -> Medicamentos | C39: 0 | D39: =SUM(Julio!$H39:$AL39) -> 0 | E39: =C39-D39 -> 0
B40: =Categorias!B36 -> Dentista Kary | C40: 0 | D40: =SUM(Julio!$H40:$AL40) -> 0 | E40: =C40-D40 -> 0
B41: =Categorias!B37 -> Dentista Thiago | C41: 0 | D41: =SUM(Julio!$H41:$AL41) -> 0 | E41: =C41-D41 -> 0
B42: =Categorias!B38 -> - | C42: 0 | D42: =SUM(Julio!$H42:$AL42) -> 0 | E42: =C42-D42 -> 0
B43: =Categorias!B39 -> - | C43: 0 | D43: =SUM(Julio!$H43:$AL43) -> 0 | E43: =C43-D43 -> 0
B45: =Categorias!B41 -> CASA | C45: =SUM(C46:C56) -> 0 | D45: =SUM(D46:D56) -> 7200 | E45: =SUM(E46:E56) -> -7200 | H45: 1 | I45: 2 | J45: 3 | K45: 4 | L45: 5 | M45: 6 | N45: 7 | O45: 8 | P45: 9 | Q45: 10 | R45: 11 | S45: 12 | T45: 13 | U45: 14 | V45: 15 | W45: 16 | X45: 17 | Y45: 18 | Z45: 19 | AA45: 20 | AB45: 21 | AC45: 22 | AD45: 23 | AE45: 24 | AF45: 25 | AG45: 26 | AH45: 27 | AI45: 28 | AJ45: 29 | AK45: 30 | AL45: 31
B46: =Categorias!B42 -> Reparación | C46: 0 | D46: =SUM(Julio!$H46:$AL46) -> 0 | E46: =C46-D46 -> 0
B47: =Categorias!B43 -> Electricidad | C47: 0 | D47: =SUM(Julio!$H47:$AL47) -> 0 | E47: =C47-D47 -> 0
B48: =Categorias!B44 -> Gas | C48: 0 | D48: =SUM(Julio!$H48:$AL48) -> 0 | E48: =C48-D48 -> 0
B49: =Categorias!B45 -> Casa Claudia | C49: 0 | D49: =SUM(Julio!$H49:$AL49) -> 0 | E49: =C49-D49 -> 0
B50: =Categorias!B46 -> Muebles/electrodomésticos | C50: 0 | D50: =SUM(Julio!$H50:$AL50) -> 200 | E50: =C50-D50 -> -200 | O50: 200
...

Sheet Agosto
B2: Presupuesto | C2: 44409
C4: Para crear un presupuesto: - A principios de este mes, rellene los campos en amarillo, despues de forma regular registre los gastos de cada dia en la tabla a la derecha - Todos los otros datos se convertirá automáticamente
C5: Fuente: | D5: =HYPERLINK("http://www.aprendizfinanciero.com/","http://www.aprendizfinanciero.com") -> http://www.aprendizfinanciero.com
B6: Ingresos
B8: Categoría | C8: Ingresos previstos | D8: Ingresos reales | E8: Diferencia | F8: Notas
B9: SUMA | C9: =C11 -> 41720.4 | D9: =D11 -> 41720.4 | E9: =E11 -> 0
B11: =Categorias!B11 -> INGRESOS TOTALES | C11: =SUM(C12:C20) -> 41720.4 | D11: =SUM(D12:D20) -> 41720.4 | E11: =SUM(E12:E20) -> 0 | H11: 1 | I11: 2 | J11: 3 | K11: 4 | L11: 5 | M11: 6 | N11: 7 | O11: 8 | P11: 9 | Q11: 10 | R11: 11 | S11: 12 | T11: 13 | U11: 14 | V11: 15 | W11: 16 | X11: 17 | Y11: 18 | Z11: 19 | AA11: 20 | AB11: 21 | AC11: 22 | AD11: 23 | AE11: 24 | AF11: 25 | AG11: 26 | AH11: 27 | AI11: 28 | AJ11: 29 | AK11: 30 | AL11: 31
B12: =Categorias!B12 -> Nomina | C12: 41720.4 | D12: =SUM(Agosto!$H12:$AL12) -> 41720.4 | E12: =D12-C12 -> 0 | V12: 20860.2 | AL12: 20860.2
B13: =Categorias!B13 -> Aguinaldo | C13: 0 | D13: =SUM(Agosto!$H13:$AL13) -> 0 | E13: =D13-C13 -> 0
B14: =Categorias!B14 -> Fondo de ahorro | C14: 0 | D14: =SUM(Agosto!$H14:$AL14) -> 0 | E14: =D14-C14 -> 0
B15: =Categorias!B15 -> Vales despensa | C15: 0 | D15: =SUM(Agosto!$H15:$AL15) -> 0 | E15: =D15-C15 -> 0
B16: =Categorias!B16 -> Vales comedor | C16: 0 | D16: =SUM(Agosto!$H16:$AL16) -> 0 | E16: =D16-C16 -> 0
B17: =Categorias!B17 -> - | C17: 0 | D17: =SUM(Agosto!$H17:$AL17) -> 0 | E17: =D17-C17 -> 0
B18: =Categorias!B18 -> - | C18: 0 | D18: =SUM(Agosto!$H18:$AL18) -> 0 | E18: =D18-C18 -> 0
B19: =Categorias!B19 -> - | C19: 0 | D19: =SUM(Agosto!$H19:$AL19) -> 0 | E19: =D19-C19 -> 0
B20: =Categorias!B20 -> - | C20: 0 | D20: =SUM(Agosto!$H20:$AL20) -> 0 | E20: =D20-C20 -> 0
B23: Gastos | H23: Registre de gastos diarios
B25: Categoría | C25: Gastos previstos | D25: Gastos reales | E25: Diferencia | F25: Notas | H25: Los campos siguientes son para un registro diario de gastos en cada categoría.
B26: SUMA | C26: =C28+C37+C45+C58+C68+C77+C88+C97+C107+C115+C126+C136+C146+C158 -> 28450 | D26: =D28+D37+D45+D58+D68+D77+D88+D97+D107+D115+D126+D136+D146+D158 -> 31090 | E26: =E28+E37+E45+E58+E68+E77+E88+E97+E107+E115+E126+E136+E146+E158 -> -2640 | H26: Si quieres incluir mas gastos en una celda, por el mismo dia, ingresa "=" y sigue la ecuación, por ejemplo:. = 25 + 20.5
B28: =Categorias!B24 -> ALIMENTOS Y BEBIDAS | C28: =SUM(C29:C35) -> 3000 | D28: =SUM(D29:D35) -> 3934 | E28: =SUM(E29:E35) -> -934 | H28: 1 | I28: 2 | J28: 3 | K28: 4 | L28: 5 | M28: 6 | N28: 7 | O28: 8 | P28: 9 | Q28: 10 | R28: 11 | S28: 12 | T28: 13 | U28: 14 | V28: 15 | W28: 16 | X28: 17 | Y28: 18 | Z28: 19 | AA28: 20 | AB28: 21 | AC28: 22 | AD28: 23 | AE28: 24 | AF28: 25 | AG28: 26 | AH28: 27 | AI28: 28 | AJ28: 29 | AK28: 30 | AL28: 31
B29: =Categorias!B25 -> Restaurantes | C29: 3000 | D29: =SUM(Agosto!$H29:$AL29) -> 3422 | E29: =C29-D29 -> -422 | M29: 600 | Q29: 250 | R29: 120 | S29: 297 | T29: 186 | U29: 634 | Y29: 900 | AA29: 45 | AE29: 89 | AF29: 89 | AL29: 212
B30: =Categorias!B26 -> Comida Carlos | C30: 0 | D30: =SUM(Agosto!$H30:$AL30) -> 512 | E30: =C30-D30 -> -512 | P30: 127 | S30: 200 | U30: 138 | Y30: 47
B31: =Categorias!B27 -> - | C31: 0 | D31: =SUM(Agosto!$H31:$AL31) -> 0 | E31: =C31-D31 -> 0
B32: =Categorias!B28 -> - | C32: 0 | D32: =SUM(Agosto!$H32:$AL32) -> 0 | E32: =C32-D32 -> 0
B33: =Categorias!B29 -> - | C33: 0 | D33: =SUM(Agosto!$H33:$AL33) -> 0 | E33: =C33-D33 -> 0
B34: =Categorias!B30 -> - | C34: 0 | D34: =SUM(Agosto!$H34:$AL34) -> 0 | E34: =C34-D34 -> 0
B35: =Categorias!B31 -> - | C35: 0 | D35: =SUM(Agosto!$H35:$AL35) -> 0 | E35: =C35-D35 -> 0
B37: =Categorias!B33 -> SALUD | C37: =SUM(C38:C43) -> 1200 | D37: =SUM(D38:D43) -> 1007 | E37: =SUM(E38:E43) -> 193 | H37: 1 | I37: 2 | J37: 3 | K37: 4 | L37: 5 | M37: 6 | N37: 7 | O37: 8 | P37: 9 | Q37: 10 | R37: 11 | S37: 12 | T37: 13 | U37: 14 | V37: 15 | W37: 16 | X37: 17 | Y37: 18 | Z37: 19 | AA37: 20 | AB37: 21 | AC37: 22 | AD37: 23 | AE37: 24 | AF37: 25 | AG37: 26 | AH37: 27 | AI37: 28 | AJ37: 29 | AK37: 30 | AL37: 31
B38: =Categorias!B34 -> Gastos en médicos | C38: 0 | D38: =SUM(Agosto!$H38:$AL38) -> 0 | E38: =C38-D38 -> 0
B39: =Categorias!B35 -> Medicamentos | C39: 0 | D39: =SUM(Agosto!$H39:$AL39) -> 1007 | E39: =C39-D39 -> -1007 | M39: 300 | U39: 83 | V39: 396 | AF39: 228
B40: =Categorias!B36 -> Dentista Kary | C40: 600 | D40: =SUM(Agosto!$H40:$AL40) -> 0 | E40: =C40-D40 -> 600
B41: =Categorias!B37 -> Dentista Thiago | C41: 600 | D41: =SUM(Agosto!$H41:$AL41) -> 0 | E41: =C41-D41 -> 600
B42: =Categorias!B38 -> - | C42: 0 | D42: =SUM(Agosto!$H42:$AL42) -> 0 | E42: =C42-D42 -> 0
B43: =Categorias!B39 -> - | C43: 0 | D43: =SUM(Agosto!$H43:$AL43) -> 0 | E43: =C43-D43 -> 0
B45: =Categorias!B41 -> CASA | C45: =SUM(C46:C56) -> 7300 | D45: =SUM(D46:D56) -> 8082 | E45: =SUM(E46:E56) -> -782 | H45: 1 | I45: 2 | J45: 3 | K45: 4 | L45: 5 | M45: 6 | N45: 7 | O45: 8 | P45: 9 | Q45: 10 | R45: 11 | S45: 12 | T45: 13 | U45: 14 | V45: 15 | W45: 16 | X45: 17 | Y45: 18 | Z45: 19 | AA45: 20 | AB45: 21 | AC45: 22 | AD45: 23 | AE45: 24 | AF45: 25 | AG45: 26 | AH45: 27 | AI45: 28 | AJ45: 29 | AK45: 30 | AL45: 31
B46: =Categorias!B42 -> Reparación | C46: 0 | D46: =SUM(Agosto!$H46:$AL46) -> 1042 | E46: =C46-D46 -> -1042 | U46: 1042
B47: =Categorias!B43 -> Electricidad | C47: 0 | D47: =SUM(Agosto!$H47:$AL47) -> 0 | E47: =C47-D47 -> 0
B48: =Categorias!B44 -> Gas | C48: 300 | D48: =SUM(Agosto!$H48:$AL48) -> 0 | E48: =C48-D48 -> 300
B49: =Categorias!B45 -> Casa Claudia | C49: 0 | D49: =SUM(Agosto!$H49:$AL49) -> 40 | E49: =C49-D49 -> -40 | U49: 40
B50: =Categorias!B46 -> Muebles/electrodomésticos | C50: 0 | D50: =SUM(Agosto!$H50:$AL50) -> 0 | E50: =C50-D50 -> 0
...

Sheet Septiembre
B2: Presupuesto | C2: 44440
C4: Para crear un presupuesto: - A principios de este mes, rellene los campos en amarillo, despues de forma regular registre los gastos de cada dia en la tabla a la derecha - Todos los otros datos se convertirá automáticamente
C5: Fuente: | D5: =HYPERLINK("http://www.aprendizfinanciero.com/","http://www.aprendizfinanciero.com") -> http://www.aprendizfinanciero.com
B6: Ingresos
B8: Categoría | C8: Ingresos previstos | D8: Ingresos reales | E8: Diferencia | F8: Notas
B9: SUMA | C9: =C11 -> 41720.4 | D9: =D11 -> 0 | E9: =E11 -> -41720.4
B11: =Categorias!B11 -> INGRESOS TOTALES | C11: =SUM(C12:C20) -> 41720.4 | D11: =SUM(D12:D20) -> 0 | E11: =SUM(E12:E20) -> -41720.4 | H11: 1 | I11: 2 | J11: 3 | K11: 4 | L11: 5 | M11: 6 | N11: 7 | O11: 8 | P11: 9 | Q11: 10 | R11: 11 | S11: 12 | T11: 13 | U11: 14 | V11: 15 | W11: 16 | X11: 17 | Y11: 18 | Z11: 19 | AA11: 20 | AB11: 21 | AC11: 22 | AD11: 23 | AE11: 24 | AF11: 25 | AG11: 26 | AH11: 27 | AI11: 28 | AJ11: 29 | AK11: 30 | AL11: 31
